Workbook

Sheet IO_msg
A1: ;group | B1: 1 | C1: MSG Ver 1.00
A2: ;RGB | B2: ;日本語 | C2: ;中国語（簡体字） | D2: ;中国語(繁体字） | E2: ;韓国語 | F2: ;英語 | G2: ;ポルトガル語 | H2: ;コメント
A3: 000000 | B3: 吸１ | C3: 吸1信号 | H3: ;DI000
A4: 000000 | B4: 吸２ | C4: 吸2信号 | H4: ;DI001
A5: 000000 | B5: 吸３ | C5: 吸3信号 | H5: ;DI002
A6: 000000 | B6: 吸４ | C6: 吸4信号 | H6: ;DI003
A7: 000000 | B7: 副チャック | C7: 副夹信号 | H7: ;DI004
A8: 000000 | B8: 抱1 | C8: 抱1信号 | H8: ;DI005
A9: 000000 | B9: 抱2 | C9: 抱2信号 | H9: ;DI008
A10: 000000 | B10: 抱3 | C10: 抱3信号 | H10: ;DI009
A11: 000000 | B11: 抱4 | C11: 抱4信号 | H11: ;DI010
A12: 000000 | B12: 空気圧力 | C12: 空气压力信号 | H12: ;DI011
A13: 000000 | B13: 姿勢 | C13: 侧姿信号 | H13: ;DI012
A14: 000000 | B14: 回正 | C14: 回正信号 | H14: ;DI013
... A222: 000000 | B222: 予備出力９５ | C222: 预留95 | H222: ;DO予備

Sheet mode_msg
A1: ;group | B1: =IO_msg!B1+1 -> 2
A2: ;RGB | B2: ;日本語 | C2: ;中国語（簡体字） | D2: ;中国語(繁体字） | E2: ;韓国語 | F2: ;英語 | G2: ;ポルトガル語 | H2: ;コメント | I2: bit address
B3: システムモード1 | C3: 系统模式1 | D3: 系統模式1 | E3: 시스템 모드 1 | F3: sysytem mode 1 | H3: ;システムモード | I3: 3472
B4: システムモード2 | C4: 系统模式2 | D4: 系統模式2 | E4: 시스템 모드 2 | F4: sysytem mode 2 | I4: =I3+1 -> 3473
B5: システムモード3 | C5: 系统模式3 | D5: 系統模式3 | E5: 시스템 모드 3 | F5: sysytem mode 3 | I5: =I4+1 -> 3474
B6: システムモード4 | C6: 系统模式4 | D6: 系統模式4 | E6: 시스템 모드 4 | F6: sysytem mode 4 | I6: =I5+1 -> 3475
B7: システムモード5 | C7: 系统模式5 | D7: 系統模式5 | E7: 시스템 모드 5 | F7: sysytem mode 5 | I7: =I6+1 -> 3476
B8: システムモード6 | C8: 系统模式6 | D8: 系統模式6 | E8: 시스템 모드 6 | F8: sysytem mode 6 | I8: =I7+1 -> 3477
B9: システムモード7 | C9: 系统模式7 | D9: 系統模式7 | E9: 시스템 모드 7 | F9: sysytem mode 7 | I9: =I8+1 -> 3478
B10: システムモード8 | C10: 系统模式8 | D10: 系統模式8 | E10: 시스템 모드 8 | F10: sysytem mode 8 | I10: =I9+1 -> 3479
B11: システムモード9 | C11: 系统模式9 | D11: 系統模式9 | E11: 시스템 모드 9 | F11: sysytem mode 9 | I11: =I10+1 -> 3480
B12: システムモード10 | C12: 系统模式10 | D12: 系統模式10 | E12: 시스템 모드 10 | F12: sysytem mode 10 | I12: =I11+1 -> 3481
B13: システムモード11 | C13: 系统模式11 | D13: 系統模式11 | E13: 시스템 모드 11 | F13: sysytem mode 11 | I13: =I12+1 -> 3482
B14: システムモード12 | C14: 系统模式12 | D14: 系統模式12 | E14: 시스템 모드 12 | F14: sysytem mode 12 | I14: =I13+1 -> 3483
B15: システムモード13 | C15: 系统模式13 | D15: 系統模式13 | E15: 시스템 모드 13 | F15: sysytem mode 13 | I15: =I14+1 -> 3484
... B18: システムモード16 | C18: 系统模式16 | D18: 系統模式16 | E18: 시스템 모드 16 | F18: sysytem mode 16 | I18: =I17+1 -> 3487
B19: ユーザーモード1 | H19: ;ユーザーモード | I19: =I18+1 -> 3488
B20: ユーザーモード2 | I20: =I19+1 -> 3489
B21: ユーザーモード3 | I21: =I20+1 -> 3490
B22: ユーザーモード4 | I22: =I21+1 -> 3491
B23: ユーザーモード5 | I23: =I22+1 -> 3492
B24: ユーザーモード6 | I24: =I23+1 -> 3493
B25: ユーザーモード7 | I25: =I24+1 -> 3494
B26: ユーザーモード8 | I26: =I25+1 -> 3495
B27: ユーザーモード9 | I27: =I26+1 -> 3496
B28: ユーザーモード10 | I28: =I27+1 -> 3497
B29: ユーザーモード11 | I29: =I28+1 -> 3498
B30: ユーザーモード12 | I30: =I29+1 -> 3499
B31: ユーザーモード13 | I31: =I30+1 -> 3500
... B50: ユーザーモード32 | I50: =I49+1 -> 3519
B51: 製品側使用 | H51: ;標準モード | I51: =I50+1 -> 3520
B52: 固定側取出 | I52: =I51+1 -> 3521
B53: 走行待機 | I53: =I52+1 -> 3522
B54: 取出下降待機 | I54: =I53+1 -> 3523
B55: 走行姿勢 | I55: =I54+1 -> 3524
B56: 前進姿勢 | I56: =I55+1 -> 3525
I57: =I56+1 -> 3526
I58: =I57+1 -> 3527
B59: 製品開放姿勢 | I59: =I58+1 -> 3528
B60: 製品分割開放 | I60: =I59+1 -> 3529
...

Sheet Ubit_msg
A1: ;group | B1: =mode_msg!B1+1 -> 3 | G1: ;Version
A2: ;RGB | B2: ;日本語 | C2: ;中国語（簡体字） | D2: ;中国語(繁体字） | E2: ;韓国語 | F2: ;英語 | G2: ;ポルトガル語 | H2: ;コメント
B3: ユーザービットメモリー000 | H3: ;IO500
B4: ユーザービットメモリー001 | H4: ;IO501
B5: ユーザービットメモリー002 | H5: ;IO502
B6: ユーザービットメモリー003 | H6: ;IO503
B7: ユーザービットメモリー004 | H7: ;IO504
B8: ユーザービットメモリー005 | H8: ;IO505
B9: ユーザービットメモリー006 | H9: ;IO506
B10: ユーザービットメモリー007 | H10: ;IO507
B11: ユーザービットメモリー008 | H11: ;IO508
B12: ユーザービットメモリー009 | H12: ;IO509
B13: ユーザービットメモリー010 | H13: ;IO50A
B14: ユーザービットメモリー011 | H14: ;IO50B
... B770: ユーザービットメモリー767 | H770: ;IO7FF

Sheet Ubyte_msg
A1: ;group | B1: =Ubit_msg!B1+1 -> 4 | G1: ;
A2: ;RGB | B2: ;日本語 | C2: ;中国語（簡体字） | D2: ;中国語(繁体字） | E2: ;韓国語 | F2: ;英語 | G2: ;ポルトガル語 | H2: ; | I2: 記号 | J2: 数 | K2: address | L2: 記号2
B3: keyNo. | H3: ; | I3: KEY | J3: 1 | K3: 10752 | L3: ;BM000
B4: dspNo.1 | H4: ; | I4: DP1 | J4: 1 | K4: =K3+J3 -> 10753 | L4: ;BM001
B5: dspNo.2 | H5: ; | I5: DP2 | J5: 1 | K5: =K4+J4 -> 10754 | L5: ;BM002
B6: ペンダントアラームNo. | H6: ; | I6: PALM | J6: 1 | K6: =K5+J5 -> 10755 | L6: ;BM003
B7: モーションアラームNo. | H7: ; | I7: MALM | J7: 1 | K7: =K6+J6 -> 10756 | L7: ;BM004
B8: 周辺アラームNo. | H8: ; | I8: EALM | J8: 1 | K8: =K7+J7 -> 10757 | L8: ;BM005
H9: ; | J9: 1 | K9: =K8+J8 -> 10758 | L9: ;BM006
H10: ; | J10: 1 | K10: =K9+J9 -> 10759 | L10: ;BM007
B11: 警報1No. | H11: ; | I11: AL1 | J11: 1 | K11: =K10+J10 -> 10760 | L11: ;BM008
B12: 警報2No. | H12: ; | I12: AL2 | J12: 1 | K12: =K11+J11 -> 10761 | L12: ;BM009
B13: 警告No. | H13: ; | I13: ERR | J13: 1 | K13: =K12+J12 -> 10762 | L13: ;BM00A
B14: 表示No. | H14: ; | I14: COM | J14: 1 | K14: =K13+J13 -> 10763 | L14: ;BM00B
B15: 教示速度 | H15: ; | I15: TCHS? | J15: 4 | K15: =K14+J14 -> 10764 | L15: ;BM00C
B16: 軸アラーム番号 | H16: ; | I16: JALM? | J16: 16 | K16: =K15+J15 -> 10768 | L16: ;BM010
B17: code mode | H17: ; | I17: CDM? | J17: 8 | K17: =K16+J16 -> 10784 | L17: ;BM020
B18: P984 標準パレタイズ設定01X | H18: ; | I18: PS01X | J18: 1 | K18: =K17+J17 -> 10792 | L18: ;BM028
B19: P984 標準パレタイズ設定01Y | H19: ; | I19: PS01Y | J19: 1 | K19: =K18+J18 -> 10793 | L19: ;BM029
B20: P984 標準パレタイズ設定01Z | H20: ; | I20: PS01Z | J20: 1 | K20: =K19+J19 -> 10794 | L20: ;BM02A
B21: P985 標準パレタイズ設定02X | H21: ; | I21: PS02X | J21: 1 | K21: =K20+J20 -> 10795 | L21: ;BM02B
B22: P985 標準パレタイズ設定02Y | H22: ; | I22: PS02Y | J22: 1 | K22: =K21+J21 -> 10796 | L22: ;BM02C
... B157: 同期指令速度 | H157: ; | I157: SYSPD | J157: 1 | K157: =K156+J156 -> 10944 | L157: ;BM0C0
H158: ; | J158: 1 | K158: =K157+J157 -> 10945 | L158: ;BM0C1
B159: 同期指令加速度 | H159: ; | I159: SYACU | J159: 1 | K159: =K158+J158 -> 10946 | L159: ;BM0C2
B160: 同期指令減速度 | H160: ; | I160: SYACD | J160: 1 | K160: =K159+J159 -> 10947 | L160: ;BM0C3
B161: ユーザーレベル | H161: ; | I161: ULEVEL | J161: 1 | K161: =K160+J160 -> 10948 | L161: ;BM0C4
B162: 選択言語 | H162: ; | I162: LANGNO | J162: 1 | K162: =K161+J161 -> 10949 | L162: ;BM0C5
B163: 画面OFF時間 | H163: ; | I163: DSPOFF | J163: 1 | K163: =K162+J162 -> 10950 | L163: ;BM0C6
B164: LCD輝度設定 | H164: ; | I164: LCDCTL | J164: 1 | K164: =K163+J163 -> 10951 | L164: ;BM0C7
H165: ; | J165: 1 | K165: =K164+J164 -> 10952 | L165: ;BM0C8
H166: ; | J166: 1 | K166: =K165+J165 -> 10953 | L166: ;BM0C9
H167: ; | J167: 1 | K167: =K166+J166 -> 10954 | L167: ;BM0CA
H168: ; | J168: 1 | K168: =K167+J167 -> 10955 | L168: ;BM0CB
H169: ; | J169: 1 | K169: =K168+J168 -> 10956 | L169: ;BM0CC
H170: ; | J170: 1 | K170: =K169+J169 -> 10957 | L170: ;BM0CD
H171: ; | J171: 1 | K171: =K170+J170 -> 10958 | L171: ;BM0CE
H172: ; | J172: 1 | K172: =K171+J171 -> 10959 | L172: ;BM0CF
B173: ユーザーバイトメモリー1 | H173: ; | I173: UBYM1 | J173: 1 | K173: =K172+J172 -> 10960 | L173: ;BM0D0
B174: ユーザーバイトメモリー2 | H174: ; | I174: UBYM2 | J174: 1 | K174: =K173+J173 -> 10961 | L174: ;BM0D1
...

Sheet Uword_msg
A1: ;group | B1: =Ubyte_msg!B1+1 -> 5 | G1: ;
B2: ;日本語 | C2: ;中国語（簡体字） | D2: ;中国語(繁体字） | E2: ;韓国語 | F2: ;英語 | G2: ;ポルトガル語 | H2: ; | I2: 記号 | J2: 数 | K2: address | L2: 記号2
B3: アナログ入力値1 | H3: ; | I3: ADIN1 | J3: 1 | K3: 11264 | L3: ;WM0000
B4: アナログ入力値2 | H4: ; | I4: ADIN2 | J4: 1 | K4: =K3+1 -> 11265 | L4: ;WM0001
B5: アナログ入力値3 | H5: ; | I5: ADIN3 | J5: 1 | K5: =K4+1 -> 11266 | L5: ;WM0002
B6: アナログ入力値4 | H6: ; | I6: ADIN4 | J6: 1 | K6: =K5+1 -> 11267 | L6: ;WM0003
B7: アナログ入力値5 | H7: ; | I7: ADIN5 | J7: 1 | K7: =K6+1 -> 11268 | L7: ;WM0004
B8: アナログ入力値6 | H8: ; | I8: ADIN6 | J8: 1 | K8: =K7+1 -> 11269 | L8: ;WM0005
B9: アナログ入力値7 | H9: ; | I9: ADIN7 | J9: 1 | K9: =K8+1 -> 11270 | L9: ;WM0006
B10: アナログ入力値8 | H10: ; | I10: ADIN8 | J10: 1 | K10: =K9+1 -> 11271 | L10: ;WM0007
B11: アナログ入力値9 | H11: ; | I11: ADIN9 | J11: 1 | K11: =K10+1 -> 11272 | L11: ;WM0008
B12: アナログ入力値10 | H12: ; | I12: ADIN10 | J12: 1 | K12: =K11+1 -> 11273 | L12: ;WM0009
B13: アナログ入力値11 | H13: ; | I13: ADIN11 | J13: 1 | K13: =K12+1 -> 11274 | L13: ;WM000A
B14: アナログ入力値12 | H14: ; | I14: ADIN12 | J14: 1 | K14: =K13+1 -> 11275 | L14: ;WM000B
B15: アナログ入力値13 | H15: ; | I15: ADIN13 | J15: 1 | K15: =K14+1 -> 11276 | L15: ;WM000C
... B42: 軸ポイント指令変数4 | H42: ; | I42: PNOR4 | J42: 1 | K42: =K41+1 -> 11303 | L42: ;WM0027
H43: ; | J43: 1 | K43: =K42+1 -> 11304 | L43: ;WM0028
H44: ; | J44: 1 | K44: =K43+1 -> 11305 | L44: ;WM0029
H45: ; | J45: 1 | K45: =K44+1 -> 11306 | L45: ;WM002A
H46: ; | J46: 1 | K46: =K45+1 -> 11307 | L46: ;WM002B
H47: ; | J47: 1 | K47: =K46+1 -> 11308 | L47: ;WM002C
H48: ; | J48: 1 | K48: =K47+1 -> 11309 | L48: ;WM002D
H49: ; | J49: 1 | K49: =K48+1 -> 11310 | L49: ;WM002E
H50: ; | J50: 1 | K50: =K49+1 -> 11311 | L50: ;WM002F
H51: ; | J51: 1 | K51: =K50+1 -> 11312 | L51: ;WM0030
H52: ; | J52: 1 | K52: =K51+1 -> 11313 | L52: ;WM0031
H53: ; | J53: 1 | K53: =K52+1 -> 11314 | L53: ;WM0032
H54: ; | J54: 1 | K54: =K53+1 -> 11315 | L54: ;WM0033
... H62: ; | J62: 1 | K62: =K61+1 -> 11323 | L62: ;WM003B
B63: 段取換要求ファイル番号 | H63: ; | I63: DRQNO | J63: 1 | K63: =K62+1 -> 11324 | L63: ;WM003C
B64: 現在使用ファイル番号 | H64: ; | I64: NOWFILE | J64: 1 | K64: =K63+1 -> 11325 | L64: ;WM003D
H65: ; | J65: 1 | K65: =K64+1 -> 11326 | L65: ;WM003E
H66: ; | J66: 1 | K66: =K65+1 -> 11327 | L66: ;WM003F
B67: ユーザーワードメモリー1 | H67: ; | I67: UWM1 | J67: 1 | K67: =K66+1 -> 11328 | L67: ;WM0040
B68: ユーザーワードメモリー2 | H68: ; | I68: UWM2 | J68: 1 | K68: =K67+1 -> 11329 | L68: ;WM0041
B69: ユーザーワードメモリー3 | H69: ; | I69: UWM3 | J69: 1 | K69: =K68+1 -> 11330 | L69: ;WM0042
B70: ユーザーワードメモリー4 | H70: ; | I70: UWM4 | J70: 1 | K70: =K69+1 -> 11331 | L70: ;WM0043
B71: ユーザーワードメモリー5 | H71: ; | I71: UWM5 | J71: 1 | K71: =K70+1 -> 11332 | L71: ;WM0044
B72: ユーザーワードメモリー6 | H72: ; | I72: UWM6 | J72: 1 | K72: =K71+1 -> 11333 | L72: ;WM0045
B73: ユーザーワードメモリー7 | H73: ; | I73: UWM7 | J73: 1 | K73: =K72+1 -> 11334 | L73: ;WM0046
...

Sheet Ulong_msg
A1: ;group | B1: =Uword_msg!B1+1 -> 6 | G1: ;
A2: ;RGB | B2: ;日本語 | C2: ;中国語（簡体字） | D2: ;中国語(繁体字） | E2: ;韓国語 | F2: ;英語 | G2: ;ポルトガル語 | H2: ; | I2: 記号 | J2: 数 | K2: address | L2: 記号2
B3: ユーザーロングメモリー1 | H3: ; | I3: ULM1 | J3: 1 | K3: 28016 | L3: ;LM0000
B4: ユーザーロングメモリー2 | H4: ; | I4: ULM2 | J4: 1 | K4: =K3+1 -> 28017 | L4: ;LM0001
B5: ユーザーロングメモリー3 | H5: ; | I5: ULM3 | J5: 1 | K5: =K4+1 -> 28018 | L5: ;LM0002
B6: ユーザーロングメモリー4 | H6: ; | I6: ULM4 | J6: 1 | K6: =K5+1 -> 28019 | L6: ;LM0003
B7: ユーザーロングメモリー5 | H7: ; | I7: ULM5 | J7: 1 | K7: =K6+1 -> 28020 | L7: ;LM0004
B8: ユーザーロングメモリー6 | H8: ; | I8: ULM6 | J8: 1 | K8: =K7+1 -> 28021 | L8: ;LM0005
B9: ユーザーロングメモリー7 | H9: ; | I9: ULM7 | J9: 1 | K9: =K8+1 -> 28022 | L9: ;LM0006
B10: ユーザーロングメモリー8 | H10: ; | I10: ULM8 | J10: 1 | K10: =K9+1 -> 28023 | L10: ;LM0007
B11: ユーザーロングメモリー9 | H11: ; | I11: ULM9 | J11: 1 | K11: =K10+1 -> 28024 | L11: ;LM0008
B12: ユーザーロングメモリー10 | H12: ; | I12: ULM10 | J12: 1 | K12: =K11+1 -> 28025 | L12: ;LM0009
B13: ユーザーロングメモリー11 | H13: ; | I13: ULM11 | J13: 1 | K13: =K12+1 -> 28026 | L13: ;LM000A
B14: ユーザーロングメモリー12 | H14: ; | I14: ULM12 | J14: 1 | K14: =K13+1 -> 28027 | L14: ;LM000B
B15: ユーザーロングメモリー13 | H15: ; | I15: ULM13 | J15: 1 | K15: =K14+1 -> 28028 | L15: ;LM000C
... B82: ユーザーロングメモリー80 | H82: ; | I82: ULM80 | J82: 1 | K82: =K81+1 -> 28095 | L82: ;LM004F
B83: ポイント位置 | H83: ; | I83: POS[ | J83: =1023*16 -> 16368 | K83: =K82+J82 -> 28096 | L83: ;LM0050
B84: タイマー設定値 | H84: ; | I84: TD??? | J84: 256 | K84: =K83+J83 -> 44464 | L84: ;LM4040
B85: カウンター設定値 | H85: ; | I85: CD??? | J85: 244 | K85: =K84+J84 -> 44720 | L85: ;LM4140
B86: 生産終了前時間設定値4 | H86: ; | I86: G4BFTM | J86: 1 | K86: =K85+J85 -> 44964 | L86: ;LM4233
B87: 1回取出個数設定値4 | H87: ; | I87: G4ONEN | J87: 1 | K87: =K86+J86 -> 44965 | L87: ;LM4234
B88: 生産予定数設定値4 | H88: ; | I88: G4PRST | J88: 1 | K88: =K87+J87 -> 44966 | L88: ;LM4235
B89: 生産終了前時間設定値3 | H89: ; | I89: G3BFTM | J89: 1 | K89: =K88+J88 -> 44967 | L89: ;LM4236
B90: 1回取出個数設定値3 | H90: ; | I90: G3ONEN | J90: 1 | K90: =K89+J89 -> 44968 | L90: ;LM4237
B91: 生産予定数設定値3 | H91: ; | I91: G3PRST | J91: 1 | K91: =K90+J90 -> 44969 | L91: ;LM4239
B92: 生産終了前時間設定値2 | H92: ; | I92: G2BFTM | J92: 1 | K92: =K91+J91 -> 44970 | L92: ;LM423A
B93: 1回取出個数設定値2 | H93: ; | I93: G2ONEN | J93: 1 | K93: =K92+J92 -> 44971 | L93: ;LM423B
B94: 生産予定数設定値2 | H94: ; | I94: G2PRST | J94: 1 | K94: =K93+J93 -> 44972 | L94: ;LM423C
B95: 生産終了前時間設定値1 | H95: ; | I95: G1BFTM | J95: 1 | K95: =K94+J94 -> 44973 | L95: ;LM423D
... B97: 生産予定数設定値1 | H97: ; | I97: G1PRST | J97: 1 | K97: =K96+J96 -> 44975 | L97: ;LM423F
B98: 軸パラメータ設定値 | H98: ; | I98: AXPAR[ | J98: =400*16 -> 6400 | K98: =K97+J97 -> 44976 | L98: ;LM4240
B99: 軸給油警告距離設定値 | H99: ; | I99: OILA? | J99: 16 | K99: =K98+J98 -> 51376 | L99: ;LM5B40
B100: タイマーカウント値 | H100: ; | I100: TC? | J100: 256 | K100: =K99+J99 -> 51392 | L100: ;LM5B50
B101: カウント値 | H101: ; | I101: CT? | J101: 236 | K101: =K100+J100 -> 51648 | L101: ;LM5C50
B102: 成型時間一時記憶4 | H102: ; | I102: G4MDTM | J102: 1 | K102: =K101+J101 -> 51884 | L102: ;LM5D3C
B103: 開放時間一時記憶4 | H103: ; | I103: G4PLTM | J103: 1 | K103: =K102+J102 -> 51885 | L103: ;LM5D3D
B104: 取出時間一時記憶4 | H104: ; | I104: G4TKTM | J104: 1 | K104: =K103+J103 -> 51886 | L104: ;LM5D3E
B105: 不良回数カウント値4 | H105: ; | I105: G4NGCT | J105: 1 | K105: =K104+J104 -> 51887 | L105: ;LM5D3F
B106: 取出回数カウント値4 | H106: ; | I106: G4PRCT | J106: 1 | K106: =K105+J105 -> 51888 | L106: ;LM5D40
B107: 成型時間一時記憶3 | H107: ; | I107: G3MDTM | J107: 1 | K107: =K106+J106 -> 51889 | L107: ;LM5D41
...

Sheet Mkey_msg
A1: ;group | B1: =Ulong_msg!B1+1 -> 7
A2: ;RGB | B2: ;日本語 | C2: ;中国語（簡体字） | D2: ;中国語(繁体字） | E2: ;韓国語 | F2: ;英語 | G2: ;ポルトガル語 | H2: ;コメント
B3: 製品チャック1 閉 | C3: 产品夹头1 关闭 | D3: 產品夾頭1 關閉 | E3: 제품 척 1 개발 | F3: Product chuck 1 close | H3: ;key20名称 Page1
B4: 製品チャック1 開 | C4: 产品夹头1 开放 | D4: 產品夾頭1 開放 | E4: 제품 척 1 닫힘 | F4: Product chuck 1 open | H4: ;key21名称
B5: 製品チャック2 閉 | C5: 产品夹头2 关闭 | D5: 產品夾頭2 關閉 | E5: 제품 척 2 개발 | F5: Product chuck 2 close | H5: ;key22名称
B6: 製品チャック2 開 | C6: 产品夹头2 开放 | D6: 產品夾頭2 開放 | E6: 제품 척 2 닫힘 | F6: Product chuck 2 open | H6: ;key23名称
B7: 製品チャック3 閉 | C7: 产品夹头3 关闭 | D7: 產品夾頭3 關閉 | E7: 제품 척 3 개발 | F7: Product chuck 3 close | H7: ;key24名称
B8: 製品チャック3 開 | C8: 产品夹头3 开放 | D8: 產品夾頭3 開放 | E8: 제품 척 3 닫힘 | F8: Product chuck 3 open | H8: ;key25名称
B9: 製品チャック4 閉 | C9: 产品夹头4 关闭 | D9: 產品夾頭4 關閉 | E9: 제품 척 4 개발 | F9: Product chuck 4 close | H9: ;key26名称
B10: 製品チャック4 開 | C10: 产品夹头4 开放 | D10: 產品夾頭4 開放 | E10: 제품 척 4 닫힘 | F10: Product chuck 4 open | H10: ;key27名称
B11: ランナーチャック 閉 | C11: 转轮夹头 关闭 | D11: 轉輪夾頭 關閉 | E11: 주자 척 개발 | F11: Runner chuck 1 close | H11: ;key28名称
B12: ランナーチャック 開 | C12: 转轮夹头 开放 | D12: 轉輪夾頭 開放 | E12: 주자 척 닫힘 | F12: Runner chuck 1 open | H12: ;key29名称
B13: 製品吸着1 閉 | H13: ;key30名称 Page2
B14: 製品吸着1 開 | H14: ;key31名称
B15: 製品吸着2 閉 | H15: ;key32名称
B16: 製品吸着2 開 | H16: ;key33名称
B17: 製品吸着3 閉 | H17: ;key34名称
B18: 製品吸着3 開 | H18: ;key35名称
B19: 製品吸着4 閉 | H19: ;key36名称
B20: 製品吸着4 開 | H20: ;key37名称
B21: ランナーチャック 閉 | H21: ;key38名称
B22: ランナーチャック 開 | H22: ;key39名称
B23: 途中開放位置 | H23: ;key40名称 Page3
B24: ランナー開放位置 | H24: ;key41名称
... B26: 前進姿勢位置 | H26: ;key43名称
H27: ;key44名称
H28: ;key45名称
H29: ;key46名称
H30: ;key47名称
H31: ;key48名称
H32: ;key49名称
H33: ;key50名称 Pgae4
H34: ;key51名称
H35: ;key52名称
H36: ;key53名称
H37: ;key54名称
H38: ;key55名称
... H82: ;key99名称

Sheet timer_msg
A1: ;group | B1: =Mkey_msg!B1+1 -> 8
A2: ;RGB | B2: ;日本語 | C2: ;中国語（簡体字） | D2: ;中国語(繁体字） | E2: ;韓国語 | F2: ;英語 | G2: ;ポルトガル語 | H2: ;コメント
B3: タイマー1 | C3: 计时器1 | D3: 計時器1 | E3: 타이머 1 | F3: timer1
B4: タイマー2 | C4: 计时器2 | D4: 計時器2 | E4: 타이머 2 | F4: timer2
B5: タイマー3 | C5: 计时器3 | D5: 計時器3 | E5: 타이머 3 | F5: timer3
B6: タイマー4 | C6: 计时器4 | D6: 計時器4 | E6: 타이머 4 | F6: timer4
B7: タイマー5 | C7: 计时器5 | D7: 計時器5 | E7: 타이머 5 | F7: timer5
B8: タイマー6 | C8: 计时器6 | D8: 計時器6 | E8: 타이머 6 | F8: timer6
B9: タイマー7 | C9: 计时器7 | D9: 計時器7 | E9: 타이머 7 | F9: timer7
B10: タイマー8 | C10: 计时器8 | D10: 計時器8 | E10: 타이머 8 | F10: timer8
B11: タイマー9 | C11: 计时器9 | D11: 計時器9 | E11: 타이머 9 | F11: timer9
B12: タイマー10 | C12: 计时器10 | D12: 計時器10 | E12: 타이머 10 | F12: timer10
B13: タイマー11 | C13: 计时器11 | D13: 計時器11 | E13: 타이머 11 | F13: timer11
B14: タイマー12 | C14: 计时器12 | D14: 計時器12 | E14: 타이머 12 | F14: timer12
... B22: タイマー20 | C22: 计时器20 | D22: 計時器20 | E22: 타이머 20 | F22: timer20
B23: タイマー21
B24: タイマー22
B25: タイマー23
B26: タイマー24
B27: タイマー25
B28: タイマー26
B29: タイマー27
B30: タイマー28
B31: タイマー29
B32: タイマー30
B33: タイマー31
B34: タイマー32
... B258: タイマー256
B263: 原点復帰 | H263: ;原点復帰画面
B264: 軸名称
B265: 現在位置
B266: 現在速度
B267: エンコーダ
B268: Ｚ相
B269: トルク
B270: HL
B271: OL
B272: MB
B273: 手動操作 | H273: ;手動操作画面
B274: 入出力 | H274: ;TAG1
...

Sheet counter_msg
A1: ;group | B1: =timer_msg!B1+1 -> 9
A2: ;RGB | B2: ;日本語 | C2: ;中国語（簡体字） | D2: ;中国語(繁体字） | E2: ;韓国語 | F2: ;英語 | G2: ;ポルトガル語 | H2: ;コメント
B3: プリセットカウンター1
B4: プリセットカウンター2
B5: プリセットカウンター3
B6: プリセットカウンター4
B7: プリセットカウンター5
B8: プリセットカウンター6
B9: プリセットカウンター7
B10: プリセットカウンター8
B11: プリセットカウンター9
B12: プリセットカウンター10
B13: プリセットカウンター11
B14: プリセットカウンター12
... B34: プリセットカウンター32

Sheet point_msg
A1: ;group | B1: =counter_msg!B1+1 -> 10
A2: ;RGB | B2: ;日本語 | C2: ;中国語（簡体字） | D2: ;中国語(繁体字） | E2: ;韓国語 | F2: ;英語 | G2: ;ポルトガル語 | H2: ;コメント
B3: 標準パレタイズ1位置 | I3: ;P984
B4: 標準パレタイズ2位置 | I4: ;P985
B5: 標準パレタイズ3位置 | I5: ;P986
B6: 標準パレタイズ4位置 | I6: ;P987
B7: 標準パレタイズ5位置 | I7: ;P988
B8: 標準パレタイズ6位置 | I8: ;P989
B9: 標準パレタイズ7位置 | I9: ;P990
B10: 標準パレタイズ8位置 | I10: ;P991
B11: 標準パレタイズ9位置 | I11: ;P992
B12: 標準パレタイズ10位置 | I12: ;P993
B13: 標準パレタイズ11位置 | I13: ;P994
B14: 標準パレタイズ12位置 | I14: ;P995
... B90: P048 | I90: ;P048

Sheet prog_msg
A1: ;group | B1: =point_msg!B1+1 -> 11
A2: ;RGB | B2: ;日本語 | C2: ;中国語（簡体字） | D2: ;中国語(繁体字） | E2: ;韓国語 | F2: ;英語 | G2: ;ポルトガル語 | H2: ;PROG #??? | I2: ;コメント
B3: メインプログラム | H3: 1
B4: ランナー取出動作 | H4: 2
B5: 標準パレタイズ動作１ | H5: 121
B6: 標準パレタイズ動作2 | H6: 122
B7: 標準パレタイズ動作3 | H7: 123
B8: 標準パレタイズ動作4 | H8: 124
B9: 標準パレタイズ動作5 | H9: 125
B10: 標準パレタイズ動作6 | H10: 126
B11: 標準パレタイズ動作7 | H11: 127
B12: 標準パレタイズ動作8 | H12: 128

Sheet ALM_msg
A1: ;group | B1: =prog_msg!B1+1 -> 12
A2: ；RGB | B2: ;日本語 | C2: ;中国語（簡体字） | D2: ;中国語(繁体字） | E2: ;韓国語 | F2: ;英語 | G2: ;ポルトガル語 | H2: ;コメント
B3: 警報：01 RUNNER確認OFFです。 RUNNERの落下およびX29のセンサー確認を 行ってください。自動継続したい場合は 動作可能スイッチを押しながらリターンキーを 押してください。
B4: 警報：02 製品確認OFFです。 製品の落下およびX19のsensor確認を 行ってください。
B5: 警報：03 製品確認OFFです。 製品の落下およびX20のsensor確認を 行ってください。
B6: 警報：04 製品確認OFFです。 製品の落下およびX21のsensor確認を 行ってください。
B7: 警報：05 製品確認OFFです。 製品の落下およびX22のsensor確認を 行ってください。
B8: 警報：06 製品確認OFFです。 製品の落下およびX23のsensor確認を 行ってください。
B9: 警報：07 製品確認OFFです。 製品の落下およびX24のsensor確認を 行ってください。
B10: 警報：08 製品確認OFFです。 製品の落下およびX25のsensor確認を 行ってください。
B11: 警報：09 製品確認OFFです。 製品の落下およびX27のsensor確認を 行ってください。
B12: 警報：10 型開完了（X46)がOFFしません。 成型許可(Y34)と型閉許可(Y35)をONして 型開完了OFF監視(T49)時間経過しても 型開完了信号(X46)がOFFしません。 型開完了OFF監視(T49)タイマーを調整してください。 成型機との信号配線 型開完了(X46),成型許可(Y34),型閉許可(Y35) を点検してください。
B13: 警報：11
B14: 警報：12 型開完了（X46)がONしません。 長時間、成型機からの型開完了がONしません。 型閉監視(T51)タイマーを調整してください。 成型機との配線信号 型開完了(X46),成型許可(Y34),型閉許可(Y35) を点検してください。
... B63: 警報：61 待機位置異常 Sz軸 Sz軸が下降待機位置監視領域外に移動しました。 Sz軸の下降待機位置の設定値および領域監視設定値を 確認してください。

Sheet ERR_msg
A1: ;group | B1: =ALM_msg!B1+1 -> 13
A2: ；RGB | B2: ;日本語 | C2: ;中国語（簡体字） | D2: ;中国語(繁体字） | E2: ;韓国語 | F2: ;英語 | G2: ;ポルトガル語 | H2: ;コメント
B3: 操作ｴﾗｰ：01 走行待機機能を選択しています。 金型を開いてください。
B4: 操作ｴﾗｰ：02 走行姿勢2機能を選択しています。 金型を開いてください。
B5: 操作ｴﾗｰ：03 フリー操作で上下軸を上昇させて下さい。
B6: 操作ｴﾗｰ：04 型開完了X46がOFF 又は 中板検知を使用していて中板信号(X35)がOFFです。 金型を開いてください。
B7: 操作ｴﾗｰ：05 原点復帰を行ってください。
B8: 操作ｴﾗｰ：06 上下軸を上昇させてください。
B9: 操作ｴﾗｰ：07 走行姿勢1,2,3機能が未選択です。この手動操作は無効です。 機能選択画面にて走行姿勢1又は走行姿勢2又は走行姿勢3を 選択してください。
B10: 操作ｴﾗｰ：08 姿勢動作を行うことが出来ません。 姿勢動作は開放側領域（X18 ON)か上下軸を上昇完了させて から行ってください。
B11: 操作ｴﾗｰ：09 取出側又は開放側へ移動させて下さい。
B12: 操作ｴﾗｰ：10 上下軸を上昇または下降させてください。
B13: 操作ｴﾗｰ：11 この操作はフリー操作画面で行ってください。
B14: 操作ｴﾗｰ：12 手動モードではありません。 手動に切換えて操作を行ってください。
... B48: 操作ｴﾗｰ：46 走行姿勢2又は3機能の選択は金型を開くか又は開放側に 移動させてから行ってください。

Sheet OPE_msg
A1: ;group | B1: =ERR_msg!B1+1 -> 14
A2: ；RGB | B2: ;日本語 | C2: ;中国語（簡体字） | D2: ;中国語(繁体字） | E2: ;韓国語 | F2: ;英語 | G2: ;ポルトガル語 | H2: ;コメント
B3: 動作表示：01 取出機の自動動作を停止させます。 しばらくお待ちください。
B4: 動作表示：02 自動動作をステップ送りモードで実行します。 この表示を消すにはRESETボタンを 押してください。 ステップ送りモードを解除する場合は もう一回「動作確認」を押してください。
B5: 動作表示：03 取出機の自動動作を停止しました。 手動に切り替えてください。
B6: 動作表示：04 原点復帰動作が完了しました。
B7: 動作表示：05 取出待機位置に移動完了しました。
B8: 動作表示：06 走行待避位置に移動完了しました。
B9: 動作表示：07 S側開放位置に移動完了しました。
B10: 動作表示：08 製品開放位置に移動完了しました。
B11: 動作表示：09 姿勢作動位置に移動完了しました。
B12: 動作表示：10 CHUCK位置に移動完了しました。
B13: 動作表示：11 インサート部品取得位置へ移動完了しました。
B14: 動作表示：12 インサート部品取得待機位置へ移動完了しました。
... B32: 動作表示：30 ステップ実行を終了しました。

Sheet SYS_msg
A1: ;group | B1: =OPE_msg!B1+1 -> 15
B2: ;日本語 | C2: ;中国語（簡体字） | D2: ;中国語(繁体字） | E2: ;韓国語 | F2: ;英語 | G2: ;ポルトガル語 | H2: ;コメント
B3: 軸ｱﾗｰﾑ：01 ROM/RAM ｴﾗｰ ｻｰﾎﾞﾄﾞﾗｲﾊﾞｰの電子部品に 異常が発見されました。 ｻｰﾎﾞﾄﾞﾗｲﾊﾞｰを交換して下さい。
B4: 軸ｱﾗｰﾑ：02 TS-LINK 通信ｴﾗｰ 通信の異常が発見されました｡ 基板のLED表示・通信ﾊｰﾈｽおよび 電源を点検して下さい。 LEDが常時点灯または 常時消灯なら基板の異常です。
B5: 軸ｱﾗｰﾑ：03 ﾓｰﾀｰ電源電圧低下異常 ﾓｰﾀｰ駆動電源が140V以下に低下しました。 電源および動力ﾊｰﾈｽの 配線・接続を点検して下さい。 異常がなければｲﾝﾊﾞｰﾀﾕﾆｯﾄを交換して下さい。
B6: 軸ｱﾗｰﾑ：04 ｴﾝｺｰﾀﾞ入力異常 ｴﾝｺｰﾀﾞ入力に異常があります。 ｴﾝｺｰﾀﾞ・ｴﾝｺｰﾀﾞﾊｰﾈｽの 配線・接続の点検を行って下さい。 異常がなければ走行ﾓｰﾀまたは ｲﾝﾊﾞｰﾀﾕﾆｯﾄを交換して下さい。
B7: 軸ｱﾗｰﾑ：05 ﾓｰﾀｰ電源OFF過負荷異常 ｴﾝｺｰﾀﾞ入力ﾊﾟﾙｽの不良または走行ﾓｰﾀｰが 回転できない状態にあります。 ｴﾝｺｰﾀﾞﾊｰﾈｽの配線・接続および 機械的過負荷の点検を行って下さい。 異常がなければ走行ﾓｰﾀまたは ｲﾝﾊﾞｰﾀﾕﾆｯﾄを交換して下さい｡
B8: 軸ｱﾗｰﾑ：06 ﾓｰﾀｰｻｰﾏﾙﾄﾘｯﾌﾟ 走行ﾓｰﾀｰのｻｰﾏﾙ入力がOFFしました｡ ｻｰﾏﾙ入力の配線・接続を点検して下さい。
B9: 軸ｱﾗｰﾑ：07 ﾓｰﾀｰ電流ｵｰﾊﾞｰ 走行ﾓｰﾀｰに30A以上の電流が流れました。 ｲﾝﾊﾞｰﾀ基板を交換して下さい。
B10: 軸ｱﾗｰﾑ：08 原点ﾘﾐｯﾄがOFFしません 原点ｻｰﾁ時に原点ﾘﾐｯﾄがOFFしません。 原点ﾘﾐｯﾄの作動状態・配線および ｴﾝｺｰﾀﾞ・ｴﾝｺｰﾀﾞｰﾊｰﾈｽの接続・配線等の 点検を行って下さい。 異常がなければｻｰﾎﾞ基板または ｻｰﾎﾞﾄﾞﾗｲﾊﾞｰを交換して下さい。
B11: 軸ｱﾗｰﾑ：09 原点以外で原点ﾘﾐｯﾄON 原点から離れても原点ﾘﾐｯﾄがOFFしません。 原点ﾘﾐｯﾄの作動状態・配線およびｴﾝｺｰﾀﾞ・ ｴﾝｺｰﾀﾞｰﾊｰﾈｽの接続・配線等の 点検を行って下さい。 異常がなければｻｰﾎﾞ基板または ｻｰﾎﾞﾄﾞﾗｲﾊﾞｰを交換して下さい。
B12: 軸ｱﾗｰﾑ：10 原点位置で原点ﾘﾐｯﾄOFF 原点移動完了時に原点ﾘﾐｯﾄがOFFしています。 原点ﾘﾐｯﾄの作動状態・配線およびｴﾝｺｰﾀﾞ・ ｴﾝｺｰﾀﾞｰﾊｰﾈｽの接続・配線等の 点検を行って下さい。 異常がなければｻｰﾎﾞ基板また。 ｻｰﾎﾞﾄﾞﾗｲﾊﾞｰを交換して下さい。
B13: 軸ｱﾗｰﾑ：11 ｵｰﾊﾞｰﾗﾝﾘﾐｯﾄ ON ｵｰﾊﾞｰﾗﾝﾘﾐｯﾄがONしました。 ｵｰﾊﾞｰﾗﾝﾘﾐｯﾄの作動状態・配線および ﾎﾟｲﾝﾄ設定値の確認を行って下さい。 【ﾘｾｯﾄ】ｷｰでｱﾗｰﾑを解除して 手動操作または原点復帰にて回避できます。
B14: 軸ｱﾗｰﾑ：12 ｻｰﾎﾞﾄﾞﾗｲﾊﾞｰ異常 ｻｰﾎﾞﾄﾞﾗｲﾊﾞ-でｱﾗｰﾑが発生しました。 下記のｱﾗｰﾑを確認してください。
... B51: 軸ｱﾗｰﾑ：50

Sheet HELP_msg
A1: ;group | B1: =SYS_msg!B1+1 -> 16
A2: ；RGB | B2: ;日本語 | C2: ;中国語（簡体字） | D2: ;中国語(繁体字） | E2: ;韓国語 | F2: ;英語 | G2: ;ポルトガル語 | H2: ;コメント
B3: 製品側アームを使用する場合 にこの機能を選択します。 この機能を選択しない場合には 製品前後軸は未使用待機位置 に移動させます。
B4: 注意！！ S側アームが選択されていない 場合にはこの機能も未使用に 設定することは出来ません。 必ずどちらかを選択するように 設定してください。
B5: 固定側に製品が成型される場合 この機能を選択します。 この機能を使う場合にはチャック を９０度オフセットして取り付け ます。
B6: 注意！！ この機能をON／OFFすると姿勢 姿勢作動・復帰出力が自動的に ON/OFFしますので干渉しない 場所に移動させてから、機能を 切り替えるようにしてください。

Sheet symbol_msg
A1: symbol1.02 Tietech
A2: ; | B2: =SUM(B3:B708) -> 220
A3: X00 | B3: 1 | C3: 1 | D3: ;DI000 | E3: ;吸１
A4: X01 | B4: 1 | C4: 2 | D4: ;DI001 | E4: ;吸２
A5: X02 | B5: 1 | C5: 3 | D5: ;DI002 | E5: ;吸３
A6: X03 | B6: 1 | C6: =B5+C5 -> 4 | D6: ;DI003 | E6: ;吸４
A7: X04 | B7: 1 | C7: =B6+C6 -> 5 | D7: ;DI004 | E7: ;チャック
A8: X05 | B8: 1 | C8: =B7+C7 -> 6 | D8: ;DI005 | E8: ;抱1
A9: X06 | B9: 1 | C9: =B8+C8 -> 7 | D9: ;DI008 | E9: ;抱2
A10: X07 | B10: 1 | C10: =B9+C9 -> 8 | D10: ;DI009 | E10: ;抱3
A11: X08 | B11: 1 | C11: =B10+C10 -> 9 | D11: ;DI010 | E11: ;抱4
A12: X09 | B12: 1 | C12: =B11+C11 -> 10 | D12: ;DI011 | E12: ;空気圧力
A13: X10 | B13: 1 | C13: =B12+C12 -> 11 | D13: ;DI012 | E13: ;姿勢
A14: X11 | B14: 1 | C14: =B13+C13 -> 12 | D14: ;DI013 | E14: ;回正
A15: X12 | B15: 1 | C15: =B14+C14 -> 13 | D15: ;DI014 | E15: ;回転
A16: X13 | B16: 1 | C16: =B15+C15 -> 14 | D16: ;DI015 | E16: ;復帰
A17: X14 | B17: 1 | C17: =B16+C16 -> 15 | D17: ;DI016 | E17: ;副臂后退
... A102: X99 | B102: 1 | C102: =B101+C101 -> 100 | D102: ;DI 予備 | E102: ;予備57
A103: Y00 | B103: 1 | C103: 1 | D103: ;DO032 | E103: ;吸1
A104: Y01 | B104: 1 | C104: =B103+C103 -> 2 | D104: ;DO033 | E104: ;吸2
A105: Y02 | B105: 1 | C105: =B104+C104 -> 3 | D105: ;DO034 | E105: ;吸3
A106: Y03 | B106: 1 | C106: =B105+C105 -> 4 | D106: ;DO035 | E106: ;吸4
A107: Y04 | B107: 1 | C107: =B106+C106 -> 5 | D107: ;DO036 | E107: ;吸5
A108: Y05 | B108: 1 | C108: =B107+C107 -> 6 | D108: ;DO037 | E108: ;夹1
A109: Y06 | B109: 1 | C109: =B108+C108 -> 7 | D109: ;DO038 | E109: ;夹2
A110: Y07 | B110: 1 | C110: =B109+C109 -> 8 | D110: ;DO039 | E110: ;夹3
A111: Y08 | B111: 1 | C111: =B110+C110 -> 9 | D111: ;DO040 | E111: ;夹4
A112: Y09 | B112: 1 | C112: =B111+C111 -> 10 | D112: ;DO041 | E112: ;副夹
A113: Y10 | B113: 1 | C113: =B112+C112 -> 11 | D113: ;DO042 | E113: ;侧姿
A114: Y11 | B114: 1 | C114: =B113+C113 -> 12 | D114: ;DO043 | E114: ;回正
A115: Y12 | B115: 1 | C115: =B114+C114 -> 13 | D115: ;DO044 | E115: ;旋转
... A222: Y119 | B222: 1 | C222: =B221+C221 -> 120 | D222: ;DO予備 | E222: ;予備出力９５

Sheet all_msg
A1: ;RGB | B1: Fontサイズ | C1: ;日本語 | D1: ;中国語（簡体字） | E1: ;中国語(繁体字） | F1: ;韓国語 | G1: ;英語 | H1: ;ポルトガル語 | I1: ;コメント
A2: ;group | B2: 20 | I2: ;全画面共通上バー
A3: FFFFFF | C3: 原点復帰 | D3: 原点模式 | E3: 原點模式 | F3: 원점 복귀 | G3: origin | I3: ;1:
A4: FFFFFF | C4: 手動操作 | D4: 手动模式 | E4: 手動模式 | F4: 수동 조작 | G4: manual | I4: ;2:
A5: FFFFFF | C5: 自動運転 | D5: 自动模式 | E5: 自動模式 | F5: 자동 운전 | G5: auto | I5: ;3:
A6: FFFFFF | C6: STEP動作 | D6: 单步模式 | E6: 單步模式 | F6: 치수 동 동작 | G6: inching | I6: ;4:
A7: FFFFFF | C7: 原点画面 | D7: 原点画面 | E7: 原點畫面 | I7: ;5:
A8: FFFFFF | C8: 手動画面 | D8: 手动画面 | E8: 手動畫面 | I8: ;6:
A9: FFFFFF | C9: 自動画面 | D9: 自动画面 | E9: 自動畫面 | I9: ;7:
A10: FFFFFF | C10: モニタ画面 | D10: 监控画面 | E10: 監控畫面 | I10: ;8:
A11: FFFFFF | C11: プログラム | D11: 标准程序 | E11: 標準程序 | I11: ;9:
A12: FFFFFF | C12: 教導画面 | D12: 教导程序 | E12: 教導程序 | I12: ;10:
A13: FFFFFF | C13: システム設定 | D13: 系统设定 | E13: 系統設定 | I13: ;11:
A14: FFFFFF | C14: 機械パラメータ | D14: 机械参数 | E14: 機械參數 | I14: ;12:
A15: FFFFFF | C15: 区域設定 | D15: 区域设定 | E15: 區域設定 | I15: ;13:
A16: FFFFFF | C16: メンテナンス | D16: 维护 | E16: 維護 | I16: ;14:
A17: FFFFFF | C17: 生産管理 | D17: 生产管理 | E17: 生產管理 | I17: ;15:
A18: FFFFFF | C18: ABS設定 | D18: ABS设定 | E18: ABS設定 | I18: ;16:
... A23: FFFFFF | C23: 副側 | D23: 副臂 | E23: 副臂 | I23: ;21:
A24: FFFFFF | C24: 0.001 | D24: 0.001 | E24: 0.001 | F24: 0.001 | G24: 0.001 | H24: 0.001 | I24: ;22:
A25: FFFFFF | C25: 0.01 | D25: 0.01 | E25: 0.01 | F25: 0.01 | G25: 0.01 | H25: 0.01 | I25: ;23:
A26: FFFFFF | C26: 0.1 | D26: 0.1 | E26: 0.1 | F26: 0.1 | G26: 0.1 | H26: 0.1 | I26: ;24:
A27: FFFFFF | C27: 低速 | D27: 低速 | E27: 低速 | I27: ;25:
A28: FFFFFF | C28: 中速 | D28: 中速 | E28: 中速 | I28: ;26:
A29: FFFFFF | C29: 高速 | D29: 高速 | E29: 高速 | I29: ;27:
I30: ;28:予備
I31: ;29:予備
A32: ;group | B32: =B2+1 -> 21 | I32: ;全画面共通下バー
A33: 000000 | C33: 原点 復帰 | D33: 原点 复归 | E33: 原點 復歸 | F33: 자동 운전 | G33: AUTO | I33: ;1:自動運転ボタン名称
A34: 000000 | C34: 手動 操作 | D34: 手动 操作 | E34: 手動 操作 | F34: 수동 조작 | G34: MANU | I34: ;2:手動操作ボタン名称
A35: 000000 | C35: 自動 操作 | D35: 自动 操作 | E35: 自動 操作 | F35: 원점 복귀 | G35: ORG | I35: ;3:設定操作ボタン名称
A36: 000000 | C36: モニタ | D36: 监控 | E36: 監控 | I36: ;4:
A37: 000000 | C37: 教導 | D37: 教导 | E37: 教導 | I37: ;5:
A38: 000000 | C38: 機能 | D38: 功能 | E38: 功能 | I38: ;6:
A39: 000000 | C39: 履歴 | D39: 履历 | E39: 履歷 | I39: ;7:
A40: 000000 | C40: 返回 | D40: 返回 | E40: 返回 | I40: ;8:
A41: 000000 | I41: ;9:予備
A42: 000000 | I42: ;10:予備
A43: 000000 | I43: ;11:予備
A44: 000000 | I44: ;12:予備
...
